#VRML_SIM R2020b utf8
WorldInfo {
  coordinateSystem "NUE"
}
Viewpoint {
  orientation -0.4405719912926205 -0.8777464811491399 -0.18830144799963147 1.2387193362802538
  position -5.983630050359864 7.614745633569768 -32.42405437361625
  follow "Formula"
  followType "Mounted Shot"
}
TexturedBackground {
  texture "noon_building_overcast"
}
TexturedBackgroundLight {
  texture "noon_building_overcast"
}
RectangleArena {
  translation 2.71 0 -60.66
  floorSize 80 80
  floorTileSize 5 5
  floorAppearance Asphalt {
  }
  wallHeight 0
}
Robot {
  translation 4.03002 0.74 -37.16
  rotation 0 1 0 -2.6179953071795863
  scale 0.25 0.25 0.25
  children [
    DistanceSensor {
      translation -3.5 0 2.94591e-05
      rotation 0 1 0 -3.1415853071795863
      name "DstSensorSpeed"
      lookupTable [
        0 1024 0
        100 2048 0
      ]
      type "laser"
      aperture 0.01
    }
    DistanceSensor {
      translation 0.35 0.7 -0.4
      rotation 0 1 0 2.3561996938995744
      name "DstSensorR"
      lookupTable [
        0 1 0
        30 2048 0
      ]
      type "laser"
      aperture 0
    }
    DistanceSensor {
      translation 0.35 0.7 0.4
      rotation 0 1 0 -2.3562003061004253
      name "DstSensorL"
      lookupTable [
        0 1 0
        30 2048 0
      ]
      type "laser"
      aperture 0
    }
    Transform {
      translation -3 -0.15 -1.25
      rotation 1 0 0 1.5707996938995747
      children [
        Hinge2Joint {
          jointParameters HingeJointParameters {
            axis 0 0 1
          }
          jointParameters2 JointParameters {
            axis 0 1 0
          }
          device [
            PositionSensor {
              name "RightSteerSensor"
            }
            RotationalMotor {
              name "RightSteer"
              minPosition -0.8
              maxPosition 0.8
              maxTorque 10000
              sound ""
            }
          ]
          device2 [
            PositionSensor {
              name "RightFrontSensor"
            }
            Brake {
              name "RightFrontBrake"
            }
          ]
          endPoint Solid {
            children [
              Shape {
                appearance Rubber {
                }
                geometry DEF FrontLeftWheel1 Cylinder {
                  height 0.5
                  radius 0.5
                }
              }
            ]
            name "Front left wheel(1)"
            boundingObject USE FrontLeftWheel1
            physics Physics {
              mass 1
            }
          }
        }
      ]
    }
    Transform {
      translation -3 -0.15 1.25
      rotation 1 0 0 1.5707996938995747
      children [
        Hinge2Joint {
          jointParameters HingeJointParameters {
            axis 0 0 1
          }
          jointParameters2 JointParameters {
            axis 0 1 0
          }
          device [
            PositionSensor {
              name "LeftSteerSensor"
            }
            RotationalMotor {
              name "LeftSteer"
              minPosition -0.8
              maxPosition 0.8
              maxTorque 10000
              sound ""
            }
          ]
          device2 [
            PositionSensor {
              name "LeftFrontSensor"
            }
            Brake {
              name "LeftFrontBrake"
            }
          ]
          endPoint Solid {
            children [
              Shape {
                appearance Rubber {
                }
                geometry DEF FrontLeftWheel1 Cylinder {
                  height 0.5
                  radius 0.5
                }
              }
            ]
            name "Front left wheel"
            boundingObject USE FrontLeftWheel1
            physics Physics {
              mass 1
            }
          }
        }
      ]
    }
    Transform {
      translation 2.45 -0.15 -1.25
      rotation 1 0 0 1.5707996938995747
      children [
        HingeJoint {
          jointParameters HingeJointParameters {
            axis 0 1 0
          }
          device [
            RotationalMotor {
              name "RightGasMotor"
              maxVelocity 50
              maxTorque 10000000
              sound ""
            }
          ]
          endPoint Solid {
            children [
              Shape {
                appearance Rubber {
                }
                geometry DEF BackLeftWheel Cylinder {
                  height 0.5
                  radius 0.5
                }
              }
            ]
            boundingObject USE BackLeftWheel
            physics Physics {
              mass 1
            }
          }
        }
      ]
    }
    Transform {
      translation 2.45 -0.15 1.25
      rotation 1 0 0 1.5707996938995747
      children [
        HingeJoint {
          jointParameters HingeJointParameters {
            axis 0 1 0
          }
          device [
            RotationalMotor {
              name "LeftGasMotor"
              acceleration 1
              maxVelocity 50
              maxTorque 10000000
              sound ""
            }
          ]
          endPoint Solid {
            children [
              Shape {
                appearance Rubber {
                }
                geometry DEF BackLeftWheel Cylinder {
                  height 0.5
                  radius 0.5
                }
              }
            ]
            name "solid(1)"
            boundingObject USE BackLeftWheel
            physics Physics {
              mass 1
            }
          }
        }
      ]
    }
    Shape {
      appearance PBRAppearance {
        baseColor 1 0 0
        roughness 1
      }
      geometry DEF FormulaBody Mesh {
        url [
          "assety/FormulaSmall2nd.obj"
        ]
      }
    }
  ]
  name "Formula"
  boundingObject USE FormulaBody
  physics Physics {
    mass 1
  }
  controller "ProjectXControler"
}
Transform {
  translation 3 0 -53.7
  scale 0.2 0.2 0.2
  children [
    Solid {
      scale 100 100 100
      children [
        DEF track2 Shape {
          appearance FormedConcrete {
            IBLStrength 2
          }
          geometry Mesh {
            url [
              "assety/TestTrackFinal.obj"
            ]
          }
          isPickable FALSE
        }
      ]
      contactMaterial "1"
      boundingObject USE track2
    }
  ]
}
